Workbook
Name CALIFICACION: Hoja2!$A$1:$A$11
Name Cantón: Hoja2!$D:$D
Name Código: Hoja2!$AA$1:$AA$56
Name Evento: Hoja2!$P$1:$P$47
Name Tipo_de_cantón: Hoja2!$G$1:$G$6

Sheet Hoja1
A1: Cantón | B1: Provincia | C1: Tipo de cantón | E1: IDM–GIRD | F1: CTI | G1: IDM–GIRD ajuatado
A2: Ambato | B2: =+VLOOKUP(Hoja1!A2,Hoja2!D1:E220,2,FALSE) -> Tungurahua | C2: Pequeño | E2: =+ROUND((C4^Hoja2!M2)*(C41^Hoja2!M3)*(C102^Hoja2!M4)*(C139^Hoja2!M5)*(C170^Hoja2!M7)*(C231^Hoja2!M7)*(C268^Hoja2!M8)*(C299^Hoja2!M9)*(C318^Hoja2!M10),3) -> 0.22 | F2: =0.8+0.4*SUM(P5:P21) -> 1.0188302 | G2: =+E2*F2 -> 0.22414264
B4: I. GOBERNANZA INSTITUCIONAL | C4: =+((D6+D12+D18+D24+D30+D36)/6)/10 -> 0.22 | F4: EVENTO | G4: CATEGORÍA | H4: SUBCATEGORÍA | I4: CANTIDAD EN EL AÑO | J4: AMENAZA | K4: VULNERABILIDAD | L4: EXPOSICIÓN | M4: MITIGACIÓN | N4: RIESGO | O4: COEFICIENTE | P4: CTIi
B5: Variable V1. Unidad Municipal de Gestión de Riesgos creada | F5: Inundaciones fluviales | G5: =+IF(F5="","",VLOOKUP(Hoja1!$F5,Hoja2!$P$1:$R$47,3,FALSE)) -> I. Eventos hidrometeorológicos | H5: =+IF(F5="","",VLOOKUP(Hoja1!F5,Hoja2!$P$1:$R$47,2,FALSE)) -> 1. Inundaciones | I5: 13 | J5: 4 | K5: 3 | L5: 5 | M5: 4 | N5: =+IF(F5="","",(J5*K5*L5/M5)/1000) -> 0.015 | O5: =+IF(F5="","",I5/SUM($I$5:$I$21)) -> 0.24528302 | P5: =+IF(F5="","",N5*O5) -> 0.0036792453
B6: P1.1 El GADM cuenta con una Unidad de Gestión Integral del Riesgo creada mediante resolución administrativa vigente. | C6: 1 | D6: =+AVERAGE(C6:C10) -> 2.2 | F6: Deslizamientos de suelo | G6: =+IF(F6="","",VLOOKUP(Hoja1!$F6,Hoja2!$P$1:$R$47,3,FALSE)) -> I. Eventos hidrometeorológicos | H6: =+IF(F6="","",VLOOKUP(Hoja1!F6,Hoja2!$P$1:$R$47,2,FALSE)) -> 2. Movimientos en masa inducidos por lluvia | I6: 40 | J6: 9 | K6: 8 | L6: 10 | M6: 1 | N6: =+IF(F6="","",(J6*K6*L6/M6)/1000) -> 0.72 | O6: =+IF(F6="","",I6/SUM($I$5:$I$21)) -> 0.75471698 | P6: =+IF(F6="","",N6*O6) -> 0.54339623
B7: P1.2 La Unidad de Gestión de Riesgos está incorporada en la estructura orgánica institucional. | C7: 3 | G7: =+IF(F7="","",VLOOKUP(Hoja1!$F7,Hoja2!$P$1:$R$47,3,FALSE)) | H7: =+IF(F7="","",VLOOKUP(Hoja1!F7,Hoja2!$P$1:$R$47,2,FALSE)) | N7: =+IF(F7="","",(J7*K7*L7/M7)/1000) | O7: =+IF(F7="","",I7/SUM($I$5:$I$21)) | P7: =+IF(F7="","",N7*O7)
B8: P1.3 La Unidad dispone de espacio físico exclusivo para el desarrollo de sus actividades. | C8: 1 | G8: =+IF(F8="","",VLOOKUP(Hoja1!$F8,Hoja2!$P$1:$R$47,3,FALSE)) | H8: =+IF(F8="","",VLOOKUP(Hoja1!F8,Hoja2!$P$1:$R$47,2,FALSE)) | N8: =+IF(F8="","",(J8*K8*L8/M8)/1000) | O8: =+IF(F8="","",I8/SUM($I$5:$I$21)) | P8: =+IF(F8="","",N8*O8)
B9: P1.4 La Unidad cuenta con equipamiento tecnológico suficiente para cumplir sus funciones. | C9: 3 | G9: =+IF(F9="","",VLOOKUP(Hoja1!$F9,Hoja2!$P$1:$R$47,3,FALSE)) | H9: =+IF(F9="","",VLOOKUP(Hoja1!F9,Hoja2!$P$1:$R$47,2,FALSE)) | N9: =+IF(F9="","",(J9*K9*L9/M9)/1000) | O9: =+IF(F9="","",I9/SUM($I$5:$I$21)) | P9: =+IF(F9="","",N9*O9)
B10: P1.5 La Unidad mantiene continuidad operativa independientemente de cambios de autoridades. | C10: 3 | G10: =+IF(F10="","",VLOOKUP(Hoja1!$F10,Hoja2!$P$1:$R$47,3,FALSE)) | H10: =+IF(F10="","",VLOOKUP(Hoja1!F10,Hoja2!$P$1:$R$47,2,FALSE)) | N10: =+IF(F10="","",(J10*K10*L10/M10)/1000) | O10: =+IF(F10="","",I10/SUM($I$5:$I$21)) | P10: =+IF(F10="","",N10*O10)
B11: Variable V2. Responsable técnico especializado | G11: =+IF(F11="","",VLOOKUP(Hoja1!$F11,Hoja2!$P$1:$R$47,3,FALSE)) | H11: =+IF(F11="","",VLOOKUP(Hoja1!F11,Hoja2!$P$1:$R$47,2,FALSE)) | N11: =+IF(F11="","",(J11*K11*L11/M11)/1000) | O11: =+IF(F11="","",I11/SUM($I$5:$I$21)) | P11: =+IF(F11="","",N11*O11)
B12: P2.1 El responsable posee formación académica relacionada con gestión del riesgo. | C12: 1 | D12: =+AVERAGE(C12:C16) -> 2.2 | G12: =+IF(F12="","",VLOOKUP(Hoja1!$F12,Hoja2!$P$1:$R$47,3,FALSE)) | H12: =+IF(F12="","",VLOOKUP(Hoja1!F12,Hoja2!$P$1:$R$47,2,FALSE)) | N12: =+IF(F12="","",(J12*K12*L12/M12)/1000) | O12: =+IF(F12="","",I12/SUM($I$5:$I$21)) | P12: =+IF(F12="","",N12*O12)
B13: P2.2 El responsable posee experiencia profesional en reducción del riesgo de desastres. | C13: 3 | G13: =+IF(F13="","",VLOOKUP(Hoja1!$F13,Hoja2!$P$1:$R$47,3,FALSE)) | H13: =+IF(F13="","",VLOOKUP(Hoja1!F13,Hoja2!$P$1:$R$47,2,FALSE)) | N13: =+IF(F13="","",(J13*K13*L13/M13)/1000) | O13: =+IF(F13="","",I13/SUM($I$5:$I$21)) | P13: =+IF(F13="","",N13*O13)
B14: P2.3 El responsable participa en programas de capacitación continua. | C14: 1 | G14: =+IF(F14="","",VLOOKUP(Hoja1!$F14,Hoja2!$P$1:$R$47,3,FALSE)) | H14: =+IF(F14="","",VLOOKUP(Hoja1!F14,Hoja2!$P$1:$R$47,2,FALSE)) | N14: =+IF(F14="","",(J14*K14*L14/M14)/1000) | O14: =+IF(F14="","",I14/SUM($I$5:$I$21)) | P14: =+IF(F14="","",N14*O14)
B15: P2.4 El responsable conoce las competencias municipales establecidas en la LOGIRD. | C15: 3 | G15: =+IF(F15="","",VLOOKUP(Hoja1!$F15,Hoja2!$P$1:$R$47,3,FALSE)) | H15: =+IF(F15="","",VLOOKUP(Hoja1!F15,Hoja2!$P$1:$R$47,2,FALSE)) | N15: =+IF(F15="","",(J15*K15*L15/M15)/1000) | O15: =+IF(F15="","",I15/SUM($I$5:$I$21)) | P15: =+IF(F15="","",N15*O15)
B16: P2.5 El perfil profesional del responsable es adecuado para dirigir procesos de gestión del riesgo. | C16: 3 | G16: =+IF(F16="","",VLOOKUP(Hoja1!$F16,Hoja2!$P$1:$R$47,3,FALSE)) | H16: =+IF(F16="","",VLOOKUP(Hoja1!F16,Hoja2!$P$1:$R$47,2,FALSE)) | N16: =+IF(F16="","",(J16*K16*L16/M16)/1000) | O16: =+IF(F16="","",I16/SUM($I$5:$I$21)) | P16: =+IF(F16="","",N16*O16)
B17: Variable V3. Número de técnicos de la UGR | G17: =+IF(F17="","",VLOOKUP(Hoja1!$F17,Hoja2!$P$1:$R$47,3,FALSE)) | H17: =+IF(F17="","",VLOOKUP(Hoja1!F17,Hoja2!$P$1:$R$47,2,FALSE)) | N17: =+IF(F17="","",(J17*K17*L17/M17)/1000) | O17: =+IF(F17="","",I17/SUM($I$5:$I$21)) | P17: =+IF(F17="","",N17*O17)
B18: P3.1 El número de técnicos asignados es suficiente para cubrir las competencias municipales. | C18: 1 | D18: =+AVERAGE(C18:C22) -> 2.2 | G18: =+IF(F18="","",VLOOKUP(Hoja1!$F18,Hoja2!$P$1:$R$47,3,FALSE)) | H18: =+IF(F18="","",VLOOKUP(Hoja1!F18,Hoja2!$P$1:$R$47,2,FALSE)) | N18: =+IF(F18="","",(J18*K18*L18/M18)/1000) | O18: =+IF(F18="","",I18/SUM($I$5:$I$21)) | P18: =+IF(F18="","",N18*O18)
B19: P3.2 El personal técnico permite atender simultáneamente procesos de prevención, mitigación, preparación y respuesta. | C19: 3 | G19: =+IF(F19="","",VLOOKUP(Hoja1!$F19,Hoja2!$P$1:$R$47,3,FALSE)) | H19: =+IF(F19="","",VLOOKUP(Hoja1!F19,Hoja2!$P$1:$R$47,2,FALSE)) | N19: =+IF(F19="","",(J19*K19*L19/M19)/1000) | O19: =+IF(F19="","",I19/SUM($I$5:$I$21)) | P19: =+IF(F19="","",N19*O19)
B20: P3.3 La Unidad cuenta con profesionales de diferentes disciplinas. | C20: 1 | G20: =+IF(F20="","",VLOOKUP(Hoja1!$F20,Hoja2!$P$1:$R$47,3,FALSE)) | H20: =+IF(F20="","",VLOOKUP(Hoja1!F20,Hoja2!$P$1:$R$47,2,FALSE)) | N20: =+IF(F20="","",(J20*K20*L20/M20)/1000) | O20: =+IF(F20="","",I20/SUM($I$5:$I$21)) | P20: =+IF(F20="","",N20*O20)
B21: P3.4 La carga laboral del personal técnico es adecuada. | C21: 3 | G21: =+IF(F21="","",VLOOKUP(Hoja1!$F21,Hoja2!$P$1:$R$47,3,FALSE)) | H21: =+IF(F21="","",VLOOKUP(Hoja1!F21,Hoja2!$P$1:$R$47,2,FALSE)) | N21: =+IF(F21="","",(J21*K21*L21/M21)/1000) | O21: =+IF(F21="","",I21/SUM($I$5:$I$21)) | P21: =+IF(F21="","",N21*O21)
B22: P3.5 Existen mecanismos para incorporar personal adicional durante emergencias. | C22: 3
B23: Variable V4. Comité Cantonal de Gestión Integral del Riesgo
B24: P4.1 El Comité Cantonal está legalmente conformado. | C24: 1 | D24: =+AVERAGE(C24:C28) -> 2.2
B25: P4.2 El Comité cuenta con reglamento interno. | C25: 3
B26: P4.3 Las instituciones integrantes participan activamente. | C26: 1
B27: P4.4 Se realiza seguimiento a los acuerdos adoptados. | C27: 3
B28: P4.5 El Comité coordina acciones interinstitucionales de forma efectiva. | C28: 3
B29: Variable V5. COE Cantonal operativo
B30: P5.1 El COE dispone de protocolos actualizados. | C30: 1 | D30: =+AVERAGE(C30:C34) -> 2.2
B31: P5.2 El COE posee instalaciones adecuadas. | C31: 3
B32: P5.3 Existen sistemas redundantes de comunicación. | C32: 1
B33: P5.4 El personal conoce sus funciones específicas. | C33: 3
B34: P5.5 El COE puede mantenerse operativo durante eventos prolongados. | C34: 3
B35: Variable V6. Sesiones anuales del COE
B36: P6.1 El COE realiza reuniones periódicas. | C36: 1 | D36: =+AVERAGE(C36:C40) -> 2.2
B37: P6.2 Las reuniones son convocadas oportunamente. | C37: 3
B38: P6.3 Se elaboran actas de cada sesión. | C38: 1
B39: P6.4 Las recomendaciones son implementadas. | C39: 3
B40: P6.5 Las sesiones contribuyen al mejoramiento institucional. | C40: 3
B41: II. PLANIFICACIÓN TERRITORIAL | C41: =+((D43+D49+D55+D61+D67+D73+D79+D85+D91+D97)/10)/10 -> 0.22
...

Sheet Hoja2
D1: Cantón | E1: Provincia | G1: Tipo de cantón | J1: Dimensión | K1: Expertos | L1: Frecuencia | M1: Coeficiente | P1: Evento | Q1: Subcategoría | R1: Categoría | AA1: Código | AB1: Tipo de variable | AC1: Variable | AD1: LOGIRD | AE1: LOOTUGS | AF1: COOTAD
A2: 1 | D2: 24 de Mayo | E2: Manabí | G2: Micro | J2: I. GOBERNANZA INSTITUCIONAL | K2: 3.3846154 | L2: =+K2/5 -> 0.67692308 | M2: =+L2/$L$11 -> 0.12464589 | P2: Inundaciones fluviales | Q2: 1. Inundaciones | R2: I. Eventos hidrometeorológicos | AA2: V1 | AB2: I. Gobernanza institucional | AC2: Unidad Municipal de Gestión de Riesgos creada | AD2: Art.20 | AE2: — | AF2: Art.140
A3: 2 | D3: Aguarico | E3: Orellana | G3: Pequeño | J3: II. PLANIFICACIÓN TERRITORIAL | K3: 3.1538462 | L3: =+K3/5 -> 0.63076923 | M3: =+L3/$L$11 -> 0.11614731 | P3: Inundaciones pluviales | Q3: 1. Inundaciones | R3: I. Eventos hidrometeorológicos | AA3: V2 | AB3: I. Gobernanza institucional | AC3: Responsable técnico con perfil especializado | AD3: Art.20 | AE3: — | AF3: —
A4: 3 | D4: Alausí | E4: Chimborazo | G4: Mediano | J4: III. PREVENCIÓN DEL RIESGO | K4: 3.0769231 | L4: =+K4/5 -> 0.61538462 | M4: =+L4/$L$11 -> 0.11331445 | P4: Inundaciones costeras | Q4: 1. Inundaciones | R4: I. Eventos hidrometeorológicos | AA4: V3 | AB4: I. Gobernanza institucional | AC4: Número de técnicos de la UGR | AD4: Art.20 | AE4: — | AF4: —
A5: 4 | D5: Ambato | E5: Tungurahua | G5: Grande | J5: IV. MITIGACIÓN DEL RIESGO | K5: 2.8461538 | L5: =+K5/5 -> 0.56923077 | M5: =+L5/$L$11 -> 0.10481586 | P5: Inundaciones por desbordamiento de lagunas | Q5: 1. Inundaciones | R5: I. Eventos hidrometeorológicos | AA5: V4 | AB5: I. Gobernanza institucional | AC5: Comité Cantonal de Gestión del Riesgo conformado | AD5: Art.22 | AE5: — | AF5: Art.140
A6: 5 | D6: Antonio Ante | E6: Imbabura | G6: Metropolitano | J6: V PREPARACIÓN Y FORTALECIMIENTO DE CAPACIDADES | K6: 3 | L6: =+K6/5 -> 0.6 | M6: =+L6/$L$11 -> 0.11048159 | P6: Inundaciones por represamiento natural | Q6: 1. Inundaciones | R6: I. Eventos hidrometeorológicos | AA6: V5 | AB6: I. Gobernanza institucional | AC6: COE cantonal operativo | AD6: Art.12.12 | AE6: — | AF6: Art.140
A7: 6 | D7: Arajuno | E7: Pastaza | J7: VI. RESPUESTA ANTE EMERGENCIAS | K7: 3 | L7: =+K7/5 -> 0.6 | M7: =+L7/$L$11 -> 0.11048159 | P7: Deslizamientos de suelo | Q7: 2. Movimientos en masa inducidos por lluvia | R7: I. Eventos hidrometeorológicos | AA7: V6 | AB7: I. Gobernanza institucional | AC7: Sesiones anuales del COE | AD7: Art.12 | AE7: — | AF7: Art.140
A8: 7 | D8: Archidona | E8: Napo | J8: VII. RECUPERACIÓN Y RECONSTRUCCIÓN | K8: 2.7692308 | L8: =+K8/5 -> 0.55384615 | M8: =+L8/$L$11 -> 0.101983 | P8: Deslizamientos rotacionales | Q8: 2. Movimientos en masa inducidos por lluvia | R8: I. Eventos hidrometeorológicos | AA8: V7 | AB8: II. Planificación territorial | AC8: PDOT incorpora gestión de riesgos | AD8: Art.9.6 | AE8: Art.11.3 | AF8: Art.295
A9: 8 | D9: Arenillas | E9: El Oro | J9: VIII. FINANCIEMIENTO Y SOSTENIBILIDAD | K9: 2.9230769 | L9: =+K9/5 -> 0.58461538 | M9: =+L9/$L$11 -> 0.10764873 | P9: Deslizamientos traslacionales | Q9: 2. Movimientos en masa inducidos por lluvia | R9: I. Eventos hidrometeorológicos | AA9: V8 | AB9: II. Planificación territorial | AC9: PUGS incorpora gestión de riesgos | AD9: Art.10 | AE9: Art.18.3 | AF9: Art.466
A10: 9 | D10: Atacames | E10: Esmeraldas | J10: IX. PARTICIPACIÓN SOCIAL Y COORDINACIÓN | K10: 3 | L10: =+K10/5 -> 0.6 | M10: =+L10/$L$11 -> 0.11048159 | P10: Derrumbes | Q10: 2. Movimientos en masa inducidos por lluvia | R10: I. Eventos hidrometeorológicos | AA10: V9 | AB10: II. Planificación territorial | AC10: Escenarios prospectivos desarrollados | AD10: Art.9 | AE10: Art.11.3 | AF10: Art.140
A11: 10 | D11: Atahualpa | E11: El Oro | L11: =+SUM(L2:L10) -> 5.4307692 | P11: Caída de rocas | Q11: 2. Movimientos en masa inducidos por lluvia | R11: I. Eventos hidrometeorológicos | AA11: V10 | AB11: II. Planificación territorial | AC11: Mapa de amenazas actualizado | AD11: Art.9.3 | AE11: Art.11.3 | AF11: Art.140
D12: Azogues | E12: Cañar | P12: Flujos de lodo | Q12: 2. Movimientos en masa inducidos por lluvia | R12: I. Eventos hidrometeorológicos | AA12: V11 | AB12: II. Planificación territorial | AC12: Mapa de riesgos actualizado | AD12: Art.9.3 | AE12: Art.11.3 | AF12: Art.140
D13: Baba | E13: Los Ríos | P13: Flujos de escombros | Q13: 2. Movimientos en masa inducidos por lluvia | R13: I. Eventos hidrometeorológicos | AA13: V12 | AB13: II. Planificación territorial | AC13: Catastro de infraestructura crítica | AD13: Art.9.3 | AE13: — | AF13: Art.55
D14: Babahoyo | E14: Los Ríos | P14: Avalanchas de lodo | Q14: 2. Movimientos en masa inducidos por lluvia | R14: I. Eventos hidrometeorológicos | AA14: V13 | AB14: II. Planificación territorial | AC14: Monitoreo permanente de amenazas | AD14: Art.9.4 | AE14: — | AF14: Art.140
D15: Balao | E15: Guayas | P15: Reptación de suelos | Q15: 2. Movimientos en masa inducidos por lluvia | R15: I. Eventos hidrometeorológicos | AA15: V14 | AB15: II. Planificación territorial | AC15: Protocolos de intercambio de información | AD15: Art.9.5 | AE15: — | AF15: Art.140
D16: Balsas | E16: El Oro | P16: Lluvias torrenciales | Q16: 3. Eventos asociados a precipitaciones intensas | R16: I. Eventos hidrometeorológicos | AA16: V15 | AB16: II. Planificación territorial | AC16: Programas comunitarios de capacitación | AD16: Art.9.7 | AE16: — | AF16: Art.54
D17: Balzar | E17: Guayas | P17: Precipitaciones extremas | Q17: 3. Eventos asociados a precipitaciones intensas | R17: I. Eventos hidrometeorológicos | AA17: V16 | AB17: II. Planificación territorial | AC17: Presupuesto destinado al conocimiento del riesgo | AD17: Art.9.8 | AE17: — | AF17: Art.249
D18: Baños de Agua Santa | E18: Tungurahua | P18: Granizadas | Q18: 3. Eventos asociados a precipitaciones intensas | R18: I. Eventos hidrometeorológicos | AA18: V17 | AB18: III. Prevención del riesgo | AC18: Ordenanza municipal de gestión de riesgos | AD18: Art.10.1 | AE18: — | AF18: Art.57
D19: Biblián | E19: Cañar | P19: Tormentas eléctricas | Q19: 3. Eventos asociados a precipitaciones intensas | R19: I. Eventos hidrometeorológicos | AA19: V18 | AB19: III. Prevención del riesgo | AC19: Normativa de control de construcciones | AD19: Art.10.3 | AE19: Art.18.3 | AF19: Art.54 literal o
D20: Bolívar | E20: Carchi | P20: Vendavales | Q20: 3. Eventos asociados a precipitaciones intensas | R20: I. Eventos hidrometeorológicos | AA20: V19 | AB20: III. Prevención del riesgo | AC20: Sistema de alerta temprana implementado | AD20: Art.10.3 | AE20: — | AF20: Art.140
D21: Bolívar | E21: Manabí | P21: Turbonadas | Q21: 3. Eventos asociados a precipitaciones intensas | R21: I. Eventos hidrometeorológicos | AA21: V20 | AB21: III. Prevención del riesgo | AC21: Sistema de información de riesgos | AD21: Art.10.3 | AE21: — | AF21: Art.140
D22: Buena Fe | E22: Los Ríos | P22: Sequías meteorológicas | Q22: 4. Eventos relacionados con déficit hídrico | R22: I. Eventos hidrometeorológicos | AA22: V21 | AB22: III. Prevención del riesgo | AC22: Campañas de prevención ejecutadas | AD22: Art.10.4 | AE22: — | AF22: Art.54
D23: Caluma | E23: Bolívar | P23: Sequías agrícolas | Q23: 4. Eventos relacionados con déficit hídrico | R23: I. Eventos hidrometeorológicos | AA23: V22 | AB23: III. Prevención del riesgo | AC23: Programas escolares de prevención | AD23: Art.10.4 | AE23: — | AF23: Art.54
... D47: Cumandá | E47: Chimborazo | P47: Explosiones industriales | Q47: 12. Accidentes tecnológicos | R47: IV. Eventos antrópicos y tecnológicos | AA47: V46 | AB47: VII. Recuperación y reconstrucción | AC47: Plan de reconstrucción elaborado | AD47: Art.16.4 | AE47: — | AF47: Art.140
D48: Cuyabeno | E48: Sucumbíos | AA48: V47 | AB48: VII. Recuperación y reconstrucción | AC48: Estrategias de «Reconstruir Mejor» | AD48: Art.16.3 | AE48: — | AF48: Art.140
D49: Daule | E49: Guayas | AA49: V48 | AB49: VII. Recuperación y reconstrucción | AC49: Continuidad de servicios básicos | AD49: Art.19.5 | AE49: — | AF49: Art.54
D50: Déleg | E50: Cañar | AA50: V49 | AB50: VIII. Financiamiento y sostenibilidad | AC50: Transferencia del riesgo | AD50: Art.19.8 | AE50: — | AF50: Art.140
D51: Durán | E51: Guayas | AA51: V50 | AB51: VIII. Financiamiento y sostenibilidad | AC51: Rendición de cuentas anual | AD51: Art.19.9 | AE51: — | AF51: Art.266
D52: Echeandía | E52: Bolívar | AA52: V51 | AB52: IX. Participación social y coordinación | AC52: Registro de instrumentos ante ente rector | AD52: Art.19.10 | AE52: — | AF52: Art.140
D53: El Carmen | E53: Manabí | AA53: V52 | AB53: IX. Participación social y coordinación | AC53: Participación ciudadana en GIRD | AD53: Art.4.10 | AE53: Art.7 | AF53: Art.304
D54: El Chaco | E54: Napo | AA54: V53 | AB54: IX. Participación social y coordinación | AC54: Participación de universidades | AD54: Art.18.9 | AE54: Art.5 | AF54: Art.144
D55: El Empalme | E55: Guayas | AA55: V54 | AB55: IX. Participación social y coordinación | AC55: Participación de comunidades vulnerables | AD55: Art.4.8 | AE55: Art.7 | AF55: Art.303
D56: El Guabo | E56: El Oro | AA56: V55 | AB56: VIII. Financiamiento y sostenibilidad | AC56: Financiamiento anual en GIRD | AD56: Art.19.7 | AE56: — | AF56: Art.249
D57: El Pan | E57: Azuay
D58: El Pangui | E58: Zamora Chinchipe
D59: El Tambo | E59: Cañar
D60: El Triunfo | E60: Guayas
D61: Eloy Alfaro | E61: Esmeraldas
D62: Esmeraldas | E62: Esmeraldas
D63: Espejo | E63: Carchi
...
